<sdf version='1.7'>
  <world name='default'>
    <light name='sun' type='directional'>
      <cast_shadows>1</cast_shadows>
      <pose>0 0 10 0 -0 0</pose>
      <diffuse>0.8 0.8 0.8 1</diffuse>
      <specular>0.2 0.2 0.2 1</specular>
      <attenuation>
        <range>1000</range>
        <constant>0.9</constant>
        <linear>0.01</linear>
        <quadratic>0.001</quadratic>
      </attenuation>
      <direction>-0.5 0.1 -0.9</direction>
      <spot>
        <inner_angle>0</inner_angle>
        <outer_angle>0</outer_angle>
        <falloff>0</falloff>
      </spot>
    </light>
    <model name='ground_plane'>
      <static>1</static>
      <link name='link'>
        <collision name='collision'>
          <geometry>
            <plane>
              <normal>0 0 1</normal>
              <size>100 100</size>
            </plane>
          </geometry>
          <surface>
            <contact>
              <collide_bitmask>65535</collide_bitmask>
              <ode/>
            </contact>
            <friction>
              <ode>
                <mu>100</mu>
                <mu2>50</mu2>
              </ode>
              <torsional>
                <ode/>
              </torsional>
            </friction>
            <bounce/>
          </surface>
          <max_contacts>10</max_contacts>
        </collision>
        <visual name='visual'>
          <cast_shadows>0</cast_shadows>
          <geometry>
            <plane>
              <normal>0 0 1</normal>
              <size>100 100</size>
            </plane>
          </geometry>
          <material>
            <script>
              <uri>file://media/materials/scripts/gazebo.material</uri>
              <name>Gazebo/Grey</name>
            </script>
          </material>
        </visual>
        <self_collide>0</self_collide>
        <enable_wind>0</enable_wind>
        <kinematic>0</kinematic>
      </link>
    </model>
    <gravity>0 0 -9.8</gravity>
    <magnetic_field>6e-06 2.3e-05 -4.2e-05</magnetic_field>
    <atmosphere type='adiabatic'/>
    <physics type='ode'>
      <max_step_size>0.001</max_step_size>
      <real_time_factor>1</real_time_factor>
      <real_time_update_rate>1000</real_time_update_rate>
    </physics>
    <scene>
      <ambient>0.4 0.4 0.4 1</ambient>
      <background>0.7 0.7 0.7 1</background>
      <shadows>1</shadows>
    </scene>
    <audio>
      <device>default</device>
    </audio>
    <wind/>
    <spherical_coordinates>
      <surface_model>EARTH_WGS84</surface_model>
      <latitude_deg>0</latitude_deg>
      <longitude_deg>0</longitude_deg>
      <elevation>0</elevation>
      <heading_deg>0</heading_deg>
    </spherical_coordinates>
    <model name='reachy'>
      <joint name='world_joint' type='fixed'>
        <pose relative_to='__model__'>0 0 1 0 -0 0</pose>
        <parent>world</parent>
        <child>torso</child>
      </joint>
      <link name='torso'>
        <pose relative_to='world_joint'>0 0 0 0 -0 0</pose>
        <inertial>
          <pose>3.8e-05 0.018892 -0.008678 0 -0 0</pose>
          <mass>0.53</mass>
          <inertia>
            <ixx>0.00290969</ixx>
            <ixy>-7.53431e-07</ixy>
            <ixz>-9.39451e-06</ixz>
            <iyy>0.00450376</iyy>
            <iyz>0.000237544</iyz>
            <izz>0.0039992</izz>
          </inertia>
        </inertial>
        <collision name='torso_collision'>
          <pose>0 0 -0.1 0 0.05 0</pose>
          <geometry>
            <box>
              <size>0.11 0.2 0.32</size>
            </box>
          </geometry>
          <surface>
            <contact>
              <ode/>
            </contact>
            <friction>
              <ode/>
              <torsional>
                <ode/>
              </torsional>
            </friction>
            <bounce/>
          </surface>
          <max_contacts>10</max_contacts>
        </collision>
        <collision name='torso_fixed_joint_lump__bottom_neck_arm_collision_1'>
          <pose>0.0067 0 0.0478 0 0.174 0</pose>
          <geometry>
            <cylinder>
              <length>0</length>
              <radius>0</radius>
            </cylinder>
          </geometry>
          <max_contacts>10</max_contacts>
          <surface>
            <contact>
              <ode/>
            </contact>
            <bounce/>
            <friction>
              <torsional>
                <ode/>
              </torsional>
              <ode/>
            </friction>
          </surface>
        </collision>
        <collision name='torso_fixed_joint_lump__middle_neck_arm_collision_2'>
          <pose>0.0067 0 0.0478 0 0.174 0</pose>
          <geometry>
            <cylinder>
              <length>0</length>
              <radius>0</radius>
            </cylinder>
          </geometry>
          <max_contacts>10</max_contacts>
          <surface>
            <contact>
              <ode/>
            </contact>
            <bounce/>
            <friction>
              <torsional>
                <ode/>
              </torsional>
              <ode/>
            </friction>
          </surface>
        </collision>
        <collision name='torso_fixed_joint_lump__top_neck_arm_collision_3'>
          <pose>0.0067 0 0.0478 0 0.174 0</pose>
          <geometry>
            <cylinder>
              <length>0</length>
              <radius>0</radius>
            </cylinder>
          </geometry>
          <max_contacts>10</max_contacts>
          <surface>
            <contact>
              <ode/>
            </contact>
            <bounce/>
            <friction>
              <torsional>
                <ode/>
              </torsional>
              <ode/>
            </friction>
          </surface>
        </collision>
        <visual name='torso_visual'>
          <pose>0 0 0 0 -0 0</pose>
          <geometry>
            <mesh>
              <scale>1 1 1</scale>
              <uri>file:///home/reachy/reachy_ws/install/reachy_description/share/reachy_description/meshes/torso.dae</uri>
            </mesh>
          </geometry>
          <material>
            <script>
              <name>Gazebo/White</name>
              <uri>file://media/materials/scripts/gazebo.material</uri>
            </script>
          </material>
        </visual>
        <visual name='torso_fixed_joint_lump__bottom_neck_arm_visual_1'>
          <pose>0.0067 0 0.0478 -0.174 0.000138 -1.57001</pose>
          <geometry>
            <mesh>
              <scale>1 1 1</scale>
              <uri>file:///home/reachy/reachy_ws/install/reachy_description/share/reachy_description/meshes/orbita_arm.dae</uri>
            </mesh>
          </geometry>
        </visual>
        <visual name='torso_fixed_joint_lump__middle_neck_arm_visual_2'>
          <pose>0.0067 0 0.0478 0.087663 -0.150497 2.61139</pose>
          <geometry>
            <mesh>
              <scale>1 1 1</scale>
              <uri>file:///home/reachy/reachy_ws/install/reachy_description/share/reachy_description/meshes/orbita_arm.dae</uri>
            </mesh>
          </geometry>
        </visual>
        <visual name='torso_fixed_joint_lump__top_neck_arm_visual_3'>
          <pose>0.0067 0 0.0478 0.087664 0.150497 0.530213</pose>
          <geometry>
            <mesh>
              <scale>1 1 1</scale>
              <uri>file:///home/reachy/reachy_ws/install/reachy_description/share/reachy_description/meshes/orbita_arm.dae</uri>
            </mesh>
          </geometry>
        </visual>
        <self_collide>0</self_collide>
        <enable_wind>0</enable_wind>
        <kinematic>0</kinematic>
      </link>
      <joint name='l_shoulder_pitch' type='revolute'>
        <pose relative_to='torso'>0 0.19 0 0 -0 0</pose>
        <parent>torso</parent>
        <child>l_shoulder</child>
        <axis>
          <xyz>0 1 0</xyz>
          <limit>
            <lower>-2.618</lower>
            <upper>1.57</upper>
            <effort>10</effort>
            <velocity>0</velocity>
          </limit>
          <dynamics>
            <damping>0.1</damping>
            <friction>0.1</friction>
            <spring_reference>0</spring_reference>
            <spring_stiffness>0</spring_stiffness>
          </dynamics>
        </axis>
      </joint>
      <link name='l_shoulder'>
        <pose relative_to='l_shoulder_pitch'>0 0 0 0 -0 0</pose>
        <inertial>
          <pose>-0.016 0.044 0 -1.57 1.57 -0</pose>
          <mass>0.053</mass>
          <inertia>
            <ixx>0.0003308</ixx>
            <ixy>9.972e-08</ixy>
            <ixz>-2.037e-09</ixz>
            <iyy>4.65e-05</iyy>
            <iyz>2.113e-06</iyz>
            <izz>3.545e-05</izz>
          </inertia>
        </inertial>
        <collision name='l_shoulder_collision'>
          <pose>0 -0.04 0 1.57079 1.57079 3.14159</pose>
          <geometry>
            <cylinder>
              <length>0.09</length>
              <radius>0.035</radius>
            </cylinder>
          </geometry>
          <max_contacts>10</max_contacts>
          <surface>
            <contact>
              <ode/>
            </contact>
            <bounce/>
            <friction>
              <torsional>
                <ode/>
              </torsional>
              <ode/>
            </friction>
          </surface>
        </collision>
        <visual name='l_shoulder_visual'>
          <pose>0 -0.04 0 1.57079 1.57079 3.14159</pose>
          <geometry>
            <mesh>
              <scale>1 1 1</scale>
              <uri>file:///home/reachy/reachy_ws/install/reachy_description/share/reachy_description/meshes/shoulder.dae</uri>
            </mesh>
          </geometry>
        </visual>
        <self_collide>0</self_collide>
        <enable_wind>0</enable_wind>
        <kinematic>0</kinematic>
      </link>
      <joint name='l_shoulder_roll' type='revolute'>
        <pose relative_to='l_shoulder'>0 0 0 0 -0 0</pose>
        <parent>l_shoulder</parent>
        <child>l_shoulder_x</child>
        <axis>
          <xyz>1 0 0</xyz>
          <limit>
            <lower>-0.174</lower>
            <upper>3.14</upper>
            <effort>10</effort>
            <velocity>0</velocity>
          </limit>
          <dynamics>
            <damping>0.1</damping>
            <friction>0.1</friction>
            <spring_reference>0</spring_reference>
            <spring_stiffness>0</spring_stiffness>
          </dynamics>
        </axis>
      </joint>
      <link name='l_shoulder_x'>
        <pose relative_to='l_shoulder_roll'>0 0 0 0 -0 0</pose>
        <inertial>
          <pose>0 0 -0.019 0 -0 0</pose>
          <mass>0.158</mass>
          <inertia>
            <ixx>68870</ixx>
            <ixy>5.393</ixy>
            <ixz>-915.5</ixz>
            <iyy>78950</iyy>
            <iyz>0.4512</iyz>
            <izz>42350</izz>
          </inertia>
        </inertial>
        <collision name='l_shoulder_x_collision'>
          <pose>0 0 -0.02 0 -0 0</pose>
          <geometry>
            <cylinder>
              <length>0.04</length>
              <radius>0.035</radius>
            </cylinder>
          </geometry>
          <max_contacts>10</max_contacts>
          <surface>
            <contact>
              <ode/>
            </contact>
            <bounce/>
            <friction>
              <torsional>
                <ode/>
              </torsional>
              <ode/>
            </friction>
          </surface>
        </collision>
        <visual name='l_shoulder_x_visual'>
          <pose>0 0 0 0 -0 0</pose>
          <geometry>
            <mesh>
              <scale>1 1 1</scale>
              <uri>file:///home/reachy/reachy_ws/install/reachy_description/share/reachy_description/meshes/shoulder_x.dae</uri>
            </mesh>
          </geometry>
        </visual>
        <self_collide>0</self_collide>
        <enable_wind>0</enable_wind>
        <kinematic>0</kinematic>
      </link>
      <joint name='l_arm_yaw' type='revolute'>
        <pose relative_to='l_shoulder_x'>0 0 0 0 -0 0</pose>
        <parent>l_shoulder_x</parent>
        <child>l_upper_arm</child>
        <axis>
          <xyz>0 0 1</xyz>
          <limit>
            <lower>-1.57</lower>
            <upper>1.57</upper>
            <effort>10</effort>
            <velocity>0</velocity>
          </limit>
          <dynamics>
            <damping>0.1</damping>
            <friction>0.1</friction>
            <spring_reference>0</spring_reference>
            <spring_stiffness>0</spring_stiffness>
          </dynamics>
        </axis>
      </joint>
      <link name='l_upper_arm'>
        <pose relative_to='l_arm_yaw'>0 0 0 0 -0 0</pose>
        <inertial>
          <pose>-0.004 0 -0.1426 0 -0 0</pose>
          <mass>0.43</mass>
          <inertia>
            <ixx>0.003264</ixx>
            <ixy>-4.027e-08</ixy>
            <ixz>0.0001395</ixz>
            <iyy>0.003345</iyy>
            <iyz>1.885e-06</iyz>
            <izz>0.0002616</izz>
          </inertia>
        </inertial>
        <collision name='l_upper_arm_collision'>
          <pose>0 0 -0.16 0 -0 0</pose>
          <geometry>
            <cylinder>
              <length>0.25</length>
              <radius>0.04</radius>
            </cylinder>
          </geometry>
          <max_contacts>10</max_contacts>
          <surface>
            <contact>
              <ode/>
            </contact>
            <bounce/>
            <friction>
              <torsional>
                <ode/>
              </torsional>
              <ode/>
            </friction>
          </surface>
        </collision>
        <visual name='l_upper_arm_visual'>
          <pose>0 0 -0.0526 0 -0 0</pose>
          <geometry>
            <mesh>
              <scale>1 1 1</scale>
              <uri>file:///home/reachy/reachy_ws/install/reachy_description/share/reachy_description/meshes/upper_arm.dae</uri>
            </mesh>
          </geometry>
        </visual>
        <self_collide>0</self_collide>
        <enable_wind>0</enable_wind>
        <kinematic>0</kinematic>
      </link>
      <joint name='l_elbow_pitch' type='revolute'>
        <pose relative_to='l_upper_arm'>0 0 -0.28 0 -0 0</pose>
        <parent>l_upper_arm</parent>
        <child>l_forearm</child>
        <axis>
          <xyz>0 1 0</xyz>
          <limit>
            <lower>-2.182</lower>
            <upper>0</upper>
            <effort>10</effort>
            <velocity>0</velocity>
          </limit>
          <dynamics>
            <damping>0.1</damping>
            <friction>0.1</friction>
            <spring_reference>0</spring_reference>
            <spring_stiffness>0</spring_stiffness>
          </dynamics>
        </axis>
      </joint>
      <link name='l_forearm'>
        <pose relative_to='l_elbow_pitch'>0 0 0 0 -0 0</pose>
        <inertial>
          <pose>-0.008 0 -0.058 0 -0 0</pose>
          <mass>0.162</mass>
          <inertia>
            <ixx>0.0002532</ixx>
            <ixy>-2.999e-08</ixy>
            <ixz>1.448e-05</ixz>
            <iyy>0.0002538</iyy>
            <iyz>-4.323e-08</iyz>
            <izz>0.0001234</izz>
          </inertia>
        </inertial>
        <collision name='l_forearm_collision'>
          <pose>0 0 -0.058 0 -0 0</pose>
          <geometry>
            <cylinder>
              <length>0.09</length>
              <radius>0.04</radius>
            </cylinder>
          </geometry>
          <max_contacts>10</max_contacts>
          <surface>
            <contact>
              <ode/>
            </contact>
            <bounce/>
            <friction>
              <torsional>
                <ode/>
              </torsional>
              <ode/>
            </friction>
          </surface>
        </collision>
        <visual name='l_forearm_visual'>
          <pose>0 0 0 0 -0 0</pose>
          <geometry>
            <mesh>
              <scale>1 1 1</scale>
              <uri>file:///home/reachy/reachy_ws/install/reachy_description/share/reachy_description/meshes/forearm.dae</uri>
            </mesh>
          </geometry>
        </visual>
        <self_collide>0</self_collide>
        <enable_wind>0</enable_wind>
        <kinematic>0</kinematic>
      </link>
      <joint name='l_forearm_yaw' type='revolute'>
        <pose relative_to='l_forearm'>0 0 0 0 -0 0</pose>
        <parent>l_forearm</parent>
        <child>l_wrist</child>
        <axis>
          <xyz>0 0 1</xyz>
          <limit>
            <lower>-1.745</lower>
            <upper>1.745</upper>
            <effort>10</effort>
            <velocity>0</velocity>
          </limit>
          <dynamics>
            <damping>0.1</damping>
            <friction>0.1</friction>
            <spring_reference>0</spring_reference>
            <spring_stiffness>0</spring_stiffness>
          </dynamics>
        </axis>
      </joint>
      <link name='l_wrist'>
        <pose relative_to='l_forearm_yaw'>0 0 0 0 -0 0</pose>
        <inertial>
          <pose>0 0 -0.193 0 -0 0</pose>
          <mass>0.197</mass>
          <inertia>
            <ixx>0.0006157</ixx>
            <ixy>5.706e-08</ixy>
            <ixz>-1.045e-05</ixz>
            <iyy>0.000628</iyy>
            <iyz>4.862e-07</iyz>
            <izz>0.000105</izz>
          </inertia>
        </inertial>
        <collision name='l_wrist_collision'>
          <pose>0 0 -0.18 0 -0 0</pose>
          <geometry>
            <cylinder>
              <length>0.14</length>
              <radius>0.035</radius>
            </cylinder>
          </geometry>
          <max_contacts>10</max_contacts>
          <surface>
            <contact>
              <ode/>
            </contact>
            <bounce/>
            <friction>
              <torsional>
                <ode/>
              </torsional>
              <ode/>
            </friction>
          </surface>
        </collision>
        <visual name='l_wrist_visual'>
          <pose>0 0 -0.1 0 -0 0</pose>
          <geometry>
            <mesh>
              <scale>1 1 1</scale>
              <uri>file:///home/reachy/reachy_ws/install/reachy_description/share/reachy_description/meshes/wrist.dae</uri>
            </mesh>
          </geometry>
        </visual>
        <self_collide>0</self_collide>
        <enable_wind>0</enable_wind>
        <kinematic>0</kinematic>
      </link>
      <joint name='l_wrist_pitch' type='revolute'>
        <pose relative_to='l_wrist'>0 0 -0.25 0 -0 0</pose>
        <parent>l_wrist</parent>
        <child>l_wrist2hand</child>
        <axis>
          <xyz>0 1 0</xyz>
          <limit>
            <lower>-0.785</lower>
            <upper>0.785</upper>
            <effort>10</effort>
            <velocity>0</velocity>
          </limit>
          <dynamics>
            <damping>0.1</damping>
            <friction>0.1</friction>
            <spring_reference>0</spring_reference>
            <spring_stiffness>0</spring_stiffness>
          </dynamics>
        </axis>
      </joint>
      <link name='l_wrist2hand'>
        <pose relative_to='l_wrist_pitch'>0 0 0 0 -0 0</pose>
        <inertial>
          <pose>0 0 0.014 0 -0 0</pose>
          <mass>0.01</mass>
          <inertia>
            <ixx>6.75e-06</ixx>
            <ixy>3.732e-11</ixy>
            <ixz>-1.581e-11</ixz>
            <iyy>6.06e-06</iyy>
            <iyz>-1.746e-12</iyz>
            <izz>5.774e-06</izz>
          </inertia>
        </inertial>
        <collision name='l_wrist2hand_collision'>
          <pose>0 0 -0.03 0 -0 0</pose>
          <geometry>
            <cylinder>
              <length>0.06</length>
              <radius>0.03</radius>
            </cylinder>
          </geometry>
          <max_contacts>10</max_contacts>
          <surface>
            <contact>
              <ode/>
            </contact>
            <bounce/>
            <friction>
              <torsional>
                <ode/>
              </torsional>
              <ode/>
            </friction>
          </surface>
        </collision>
        <visual name='l_wrist2hand_visual'>
          <pose>0 0 0 0 -0 0</pose>
          <geometry>
            <mesh>
              <scale>1 1 1</scale>
              <uri>file:///home/reachy/reachy_ws/install/reachy_description/share/reachy_description/meshes/wrist2hand.dae</uri>
            </mesh>
          </geometry>
        </visual>
        <self_collide>0</self_collide>
        <enable_wind>0</enable_wind>
        <kinematic>0</kinematic>
      </link>
      <joint name='l_wrist_roll' type='revolute'>
        <pose relative_to='l_wrist2hand'>0 0 -0.0325 0 -0 0</pose>
        <parent>l_wrist2hand</parent>
        <child>l_gripper_thumb</child>
        <axis>
          <xyz>1 0 0</xyz>
          <limit>
            <lower>-0.785</lower>
            <upper>0.785</upper>
            <effort>10</effort>
            <velocity>0</velocity>
          </limit>
          <dynamics>
            <damping>0.1</damping>
            <friction>0.1</friction>
            <spring_reference>0</spring_reference>
            <spring_stiffness>0</spring_stiffness>
          </dynamics>
        </axis>
      </joint>
      <link name='l_gripper_thumb'>
        <pose relative_to='l_wrist_roll'>0 0 0 0 -0 0</pose>
        <inertial>
          <pose>0.031816 0.007885 -0.000489 0 1.57 0</pose>
          <mass>0.174</mass>
          <inertia>
            <ixx>0.000110716</ixx>
            <ixy>-3.30798e-05</ixy>
            <ixz>4.02537e-06</ixz>
            <iyy>0.000151302</iyy>
            <iyz>4.66782e-08</iyz>
            <izz>0.000219781</izz>
          </inertia>
        </inertial>
        <collision name='l_gripper_thumb_collision'>
          <pose>0 0 0 3.14159 1.57079 3.14159</pose>
          <geometry>
            <mesh>
              <scale>1 1 1</scale>
              <uri>file:///home/reachy/reachy_ws/install/reachy_description/share/reachy_description/meshes/l_gripper_thumb.dae</uri>
            </mesh>
          </geometry>
          <surface>
            <contact>
              <ode/>
            </contact>
            <friction>
              <ode/>
              <torsional>
                <ode/>
              </torsional>
            </friction>
            <bounce/>
          </surface>
          <max_contacts>10</max_contacts>
        </collision>
        <visual name='l_gripper_thumb_visual'>
          <pose>0 0 0 3.14159 1.57079 3.14159</pose>
          <geometry>
            <mesh>
              <scale>1 1 1</scale>
              <uri>file:///home/reachy/reachy_ws/install/reachy_description/share/reachy_description/meshes/l_gripper_thumb.dae</uri>
            </mesh>
          </geometry>
        </visual>
        <self_collide>1</self_collide>
        <enable_wind>0</enable_wind>
        <kinematic>0</kinematic>
      </link>
      <joint name='l_gripper' type='revolute'>
        <pose relative_to='l_gripper_thumb'>0 0.037 -0.03998 0 -0 0</pose>
        <parent>l_gripper_thumb</parent>
        <child>l_gripper_finger</child>
        <axis>
          <xyz>1 0 0</xyz>
          <limit>
            <lower>-0.35</lower>
            <upper>1.2</upper>
            <effort>10</effort>
            <velocity>0</velocity>
          </limit>
          <dynamics>
            <damping>0.1</damping>
            <friction>0.1</friction>
            <spring_reference>0</spring_reference>
            <spring_stiffness>0</spring_stiffness>
          </dynamics>
        </axis>
        <physics>
          <provide_feedback>1</provide_feedback>
          <ode>
            <limit>
              <cfm>0</cfm>
              <erp>0.2</erp>
            </limit>
            <provide_feedback>1</provide_feedback>
          </ode>
        </physics>
      </joint>
      <link name='l_gripper_finger'>
        <pose relative_to='l_gripper'>0 0 0 0 -0 0</pose>
        <inertial>
          <pose>0.005 -0.043 0 0 1.57 0</pose>
          <mass>0.035</mass>
          <inertia>
            <ixx>9.166e-05</ixx>
            <ixy>-6.559e-06</ixy>
            <ixz>-3.952e-08</ixz>
            <iyy>1.062e-05</iyy>
            <iyz>5.276e-09</iyz>
            <izz>8.704e-05</izz>
          </inertia>
        </inertial>
        <collision name='l_gripper_finger_collision'>
          <pose>0 0 0 3.14159 1.57079 3.14159</pose>
          <geometry>
            <mesh>
              <scale>1 1 1</scale>
              <uri>file:///home/reachy/reachy_ws/install/reachy_description/share/reachy_description/meshes/l_gripper_finger.dae</uri>
            </mesh>
          </geometry>
          <surface>
            <contact>
              <ode/>
            </contact>
            <friction>
              <ode/>
              <torsional>
                <ode/>
              </torsional>
            </friction>
            <bounce/>
          </surface>
          <max_contacts>10</max_contacts>
        </collision>
        <visual name='l_gripper_finger_visual'>
          <pose>0 0 0 3.14159 1.57079 3.14159</pose>
          <geometry>
            <mesh>
              <scale>1 1 1</scale>
              <uri>file:///home/reachy/reachy_ws/install/reachy_description/share/reachy_description/meshes/l_gripper_finger.dae</uri>
            </mesh>
          </geometry>
        </visual>
        <self_collide>1</self_collide>
        <enable_wind>0</enable_wind>
        <kinematic>0</kinematic>
      </link>
      <joint name='neck_roll' type='revolute'>
        <pose relative_to='torso'>0.015 0 0.095 0 0.174 0</pose>
        <parent>torso</parent>
        <child>head_x</child>
        <axis>
          <xyz>1 0 0</xyz>
          <limit>
            <lower>-0.8</lower>
            <upper>0.8</upper>
            <effort>10</effort>
            <velocity>0</velocity>
          </limit>
          <dynamics>
            <damping>0.1</damping>
            <friction>0.1</friction>
            <spring_reference>0</spring_reference>
            <spring_stiffness>0</spring_stiffness>
          </dynamics>
        </axis>
      </joint>
      <link name='head_x'>
        <pose relative_to='neck_roll'>0 0 0 0 -0 0</pose>
        <inertial>
          <pose>0 0 0 0 -0 0</pose>
          <mass>0.001</mass>
          <inertia>
            <ixx>1e-06</ixx>
            <ixy>1e-08</ixy>
            <ixz>1e-08</ixz>
            <iyy>1e-06</iyy>
            <iyz>1e-08</iyz>
            <izz>1e-06</izz>
          </inertia>
        </inertial>
        <self_collide>0</self_collide>
        <enable_wind>0</enable_wind>
        <kinematic>0</kinematic>
      </link>
      <joint name='neck_pitch' type='revolute'>
        <pose relative_to='head_x'>0 0 0 0 -0 0</pose>
        <parent>head_x</parent>
        <child>head_y</child>
        <axis>
          <xyz>0 1 0</xyz>
          <limit>
            <lower>-0.8</lower>
            <upper>1.13</upper>
            <effort>10</effort>
            <velocity>0</velocity>
          </limit>
          <dynamics>
            <damping>0.1</damping>
            <friction>0.1</friction>
            <spring_reference>0</spring_reference>
            <spring_stiffness>0</spring_stiffness>
          </dynamics>
        </axis>
      </joint>
      <link name='head_y'>
        <pose relative_to='neck_pitch'>0 0 0 0 -0 0</pose>
        <inertial>
          <pose>0 0 0 0 -0 0</pose>
          <mass>0.001</mass>
          <inertia>
            <ixx>1e-06</ixx>
            <ixy>1e-08</ixy>
            <ixz>1e-08</ixz>
            <iyy>1e-06</iyy>
            <iyz>1e-08</iyz>
            <izz>1e-06</izz>
          </inertia>
        </inertial>
        <self_collide>0</self_collide>
        <enable_wind>0</enable_wind>
        <kinematic>0</kinematic>
      </link>
      <joint name='neck_yaw' type='revolute'>
        <pose relative_to='head_y'>0 0 0 0 -0 0</pose>
        <parent>head_y</parent>
        <child>head_z</child>
        <axis>
          <xyz>0 0 1</xyz>
          <limit>
            <lower>-2.79</lower>
            <upper>2.79</upper>
            <effort>10</effort>
            <velocity>0</velocity>
          </limit>
          <dynamics>
            <damping>0.1</damping>
            <friction>0.1</friction>
            <spring_reference>0</spring_reference>
            <spring_stiffness>0</spring_stiffness>
          </dynamics>
        </axis>
      </joint>
      <link name='head_z'>
        <pose relative_to='neck_yaw'>0 0 0 0 -0 0</pose>
        <inertial>
          <pose>-0.008959 -0.001991 0.058752 0 -0 0</pose>
          <mass>0.23803</mass>
          <inertia>
            <ixx>0.0016835</ixx>
            <ixy>3.05835e-06</ixy>
            <ixz>0.000125027</ixz>
            <iyy>0.00137557</iyy>
            <iyz>3.37274e-05</iyz>
            <izz>0.000846636</izz>
          </inertia>
        </inertial>
        <collision name='head_z_fixed_joint_lump__head_collision'>
          <pose>-0.009 -0.002 0.059 1.57 -0 0</pose>
          <geometry>
            <cylinder>
              <length>0.15</length>
              <radius>0.06</radius>
            </cylinder>
          </geometry>
          <max_contacts>10</max_contacts>
          <surface>
            <contact>
              <ode/>
            </contact>
            <bounce/>
            <friction>
              <torsional>
                <ode/>
              </torsional>
              <ode/>
            </friction>
          </surface>
        </collision>
        <visual name='head_z_fixed_joint_lump__head_visual'>
          <pose>0 0 0 0 -0 0</pose>
          <geometry>
            <mesh>
              <scale>1 1 1</scale>
              <uri>file:///home/reachy/reachy_ws/install/reachy_description/share/reachy_description/meshes/head.dae</uri>
            </mesh>
          </geometry>
        </visual>
        <sensor name='depth_camera' type='depth'>
          <always_on>1</always_on>
          <update_rate>15</update_rate>
          <camera name='realsense_depth_camera'>
            <horizontal_fov>1.46608</horizontal_fov>
            <image>
              <width>424</width>
              <height>240</height>
              <format>B8G8R8</format>
            </image>
            <clip>
              <near>0.05</near>
              <far>8</far>
            </clip>
          </camera>
          <plugin name='intel_realsense_r200_depth_driver' filename='libgazebo_ros_camera.so'>
            <ros>
              <namespace>depth_camera</namespace>
              <remapping>depth_camera/image_raw:=color/image_raw</remapping>
              <remapping>depth_camera/depth/image_raw:=depth/image_rect_raw</remapping>
              <remapping>depth_camera/camera_info:=camera_info</remapping>
              <remapping>depth_camera/depth/camera_info:=depth/camera_info</remapping>
              <remapping>depth_camera/points:=depth/points</remapping>
            </ros>
            <camera_name>depth_camera</camera_name>
            <frame_name>depth_camera_optical</frame_name>
            <hack_baseline>0.07</hack_baseline>
            <min_depth>0.05</min_depth>
            <max_depth>8.0</max_depth>
          </plugin>
          <pose>0.02 0 0.06105 0 -0 0</pose>
        </sensor>
        <sensor name='left_camera' type='camera'>
          <always_on>0</always_on>
          <update_rate>30</update_rate>
          <camera name='left_camera'>
            <horizontal_fov>1.39626</horizontal_fov>
            <image>
              <width>800</width>
              <height>800</height>
              <format>R8G8B8</format>
            </image>
            <distortion>
              <k1>0</k1>
              <k2>0</k2>
              <k3>0</k3>
              <p1>0</p1>
              <p2>0</p2>
              <center>0.5 0.5</center>
            </distortion>
            <noise>
              <type>gaussian</type>
              <mean>0</mean>
              <stddev>0.007</stddev>
            </noise>
            <clip>
              <near>0.1</near>
              <far>100</far>
            </clip>
          </camera>
          <plugin name='left_camera_controller' filename='libgazebo_ros_camera.so'>
            <ros>
              <namespace>/</namespace>
              <remapping>image_raw:=image_raw</remapping>
              <remapping>camera_info:=camera_info</remapping>
            </ros>
            <camera_name>left_image</camera_name>
            <frame_name>left_camera_optical</frame_name>
            <hack_baseline>0.07</hack_baseline>
          </plugin>
          <pose>0.02 0.03625 0.06105 0 -0 0</pose>
        </sensor>
        <sensor name='right_camera' type='camera'>
          <always_on>0</always_on>
          <update_rate>30</update_rate>
          <camera name='right_camera'>
            <horizontal_fov>1.39626</horizontal_fov>
            <image>
              <width>800</width>
              <height>800</height>
              <format>R8G8B8</format>
            </image>
            <distortion>
              <k1>0</k1>
              <k2>0</k2>
              <k3>0</k3>
              <p1>0</p1>
              <p2>0</p2>
              <center>0.5 0.5</center>
            </distortion>
            <noise>
              <type>gaussian</type>
              <mean>0</mean>
              <stddev>0.007</stddev>
            </noise>
            <clip>
              <near>0.1</near>
              <far>100</far>
            </clip>
          </camera>
          <plugin name='right_camera_controller' filename='libgazebo_ros_camera.so'>
            <ros>
              <namespace>/</namespace>
              <remapping>image_raw:=image_raw</remapping>
              <remapping>camera_info:=camera_info</remapping>
            </ros>
            <camera_name>right_image</camera_name>
            <frame_name>right_camera_optical</frame_name>
            <hack_baseline>0.07</hack_baseline>
          </plugin>
          <pose>0.02 -0.03625 0.06105 0 -0 0</pose>
        </sensor>
        <self_collide>0</self_collide>
        <enable_wind>0</enable_wind>
        <kinematic>0</kinematic>
      </link>
      <joint name='l_antenna' type='revolute'>
        <pose relative_to='head_z'>-0.052 0.057 0.086 0.166 -1.054 -1.11</pose>
        <parent>head_z</parent>
        <child>l_antenna_link</child>
        <axis>
          <xyz>0 0 1</xyz>
          <limit>
            <lower>-2.618</lower>
            <upper>2.618</upper>
            <effort>10</effort>
            <velocity>0</velocity>
          </limit>
          <dynamics>
            <spring_reference>0</spring_reference>
            <spring_stiffness>0</spring_stiffness>
          </dynamics>
        </axis>
      </joint>
      <link name='l_antenna_link'>
        <pose relative_to='l_antenna'>0 0 0 0 -0 0</pose>
        <inertial>
          <pose>-0.001 0 0.008 0 -0 0</pose>
          <mass>0.004</mass>
          <inertia>
            <ixx>1.794e-07</ixx>
            <ixy>-1.24e-05</ixy>
            <ixz>1.91701e-08</ixz>
            <iyy>1.5e-07</iyy>
            <iyz>3.169e-06</iyz>
            <izz>1.933e-07</izz>
          </inertia>
        </inertial>
        <collision name='l_antenna_link_collision'>
          <pose>0.1 0 0.1 0 -0 0</pose>
          <geometry>
            <cylinder>
              <length>0</length>
              <radius>0</radius>
            </cylinder>
          </geometry>
          <max_contacts>10</max_contacts>
          <surface>
            <contact>
              <ode/>
            </contact>
            <bounce/>
            <friction>
              <torsional>
                <ode/>
              </torsional>
              <ode/>
            </friction>
          </surface>
        </collision>
        <visual name='l_antenna_link_visual'>
          <pose>0 0 0 0 -0 0</pose>
          <geometry>
            <mesh>
              <scale>1 1 1</scale>
              <uri>file:///home/reachy/reachy_ws/install/reachy_description/share/reachy_description/meshes/antenna.dae</uri>
            </mesh>
          </geometry>
        </visual>
        <self_collide>0</self_collide>
        <enable_wind>0</enable_wind>
        <kinematic>0</kinematic>
      </link>
      <joint name='r_antenna' type='revolute'>
        <pose relative_to='head_z'>-0.052 -0.057 0.086 -0.166 -1.054 1.11</pose>
        <parent>head_z</parent>
        <child>r_antenna_link</child>
        <axis>
          <xyz>0 0 1</xyz>
          <limit>
            <lower>-2.618</lower>
            <upper>2.618</upper>
            <effort>10</effort>
            <velocity>0</velocity>
          </limit>
          <dynamics>
            <spring_reference>0</spring_reference>
            <spring_stiffness>0</spring_stiffness>
          </dynamics>
        </axis>
      </joint>
      <link name='r_antenna_link'>
        <pose relative_to='r_antenna'>0 0 0 0 -0 0</pose>
        <inertial>
          <pose>-0.001 0 0.008 0 -0 0</pose>
          <mass>0.004</mass>
          <inertia>
            <ixx>1.794e-07</ixx>
            <ixy>-1.24e-05</ixy>
            <ixz>1.91701e-08</ixz>
            <iyy>1.5e-07</iyy>
            <iyz>3.169e-06</iyz>
            <izz>1.933e-07</izz>
          </inertia>
        </inertial>
        <collision name='r_antenna_link_collision'>
          <pose>0 0 0 0 -0 0</pose>
          <geometry>
            <cylinder>
              <length>0</length>
              <radius>0</radius>
            </cylinder>
          </geometry>
          <max_contacts>10</max_contacts>
          <surface>
            <contact>
              <ode/>
            </contact>
            <bounce/>
            <friction>
              <torsional>
                <ode/>
              </torsional>
              <ode/>
            </friction>
          </surface>
        </collision>
        <visual name='r_antenna_link_visual'>
          <pose>0 0 0 0 -0 0</pose>
          <geometry>
            <mesh>
              <scale>1 1 1</scale>
              <uri>file:///home/reachy/reachy_ws/install/reachy_description/share/reachy_description/meshes/antenna.dae</uri>
            </mesh>
          </geometry>
        </visual>
        <self_collide>0</self_collide>
        <enable_wind>0</enable_wind>
        <kinematic>0</kinematic>
      </link>
      <joint name='r_shoulder_pitch' type='revolute'>
        <pose relative_to='torso'>0 -0.19 0 0 -0 0</pose>
        <parent>torso</parent>
        <child>r_shoulder</child>
        <axis>
          <xyz>0 1 0</xyz>
          <limit>
            <lower>-2.618</lower>
            <upper>1.57</upper>
            <effort>10</effort>
            <velocity>0</velocity>
          </limit>
          <dynamics>
            <damping>0.1</damping>
            <friction>0.1</friction>
            <spring_reference>0</spring_reference>
            <spring_stiffness>0</spring_stiffness>
          </dynamics>
        </axis>
      </joint>
      <link name='r_shoulder'>
        <pose relative_to='r_shoulder_pitch'>0 0 0 0 -0 0</pose>
        <inertial>
          <pose>-0.016 0.036 0 1.57 1.57 0</pose>
          <mass>0.053</mass>
          <inertia>
            <ixx>0.0003308</ixx>
            <ixy>9.972e-08</ixy>
            <ixz>-2.037e-09</ixz>
            <iyy>4.65e-05</iyy>
            <iyz>2.113e-06</iyz>
            <izz>3.545e-05</izz>
          </inertia>
        </inertial>
        <collision name='r_shoulder_collision'>
          <pose>0 0.04 0 -1.57079 1.57079 3.14159</pose>
          <geometry>
            <cylinder>
              <length>0.09</length>
              <radius>0.035</radius>
            </cylinder>
          </geometry>
          <max_contacts>10</max_contacts>
          <surface>
            <contact>
              <ode/>
            </contact>
            <bounce/>
            <friction>
              <torsional>
                <ode/>
              </torsional>
              <ode/>
            </friction>
          </surface>
        </collision>
        <visual name='r_shoulder_visual'>
          <pose>0 0.04 0 -1.57079 1.57079 3.14159</pose>
          <geometry>
            <mesh>
              <scale>1 1 1</scale>
              <uri>file:///home/reachy/reachy_ws/install/reachy_description/share/reachy_description/meshes/shoulder.dae</uri>
            </mesh>
          </geometry>
        </visual>
        <self_collide>0</self_collide>
        <enable_wind>0</enable_wind>
        <kinematic>0</kinematic>
      </link>
      <joint name='r_shoulder_roll' type='revolute'>
        <pose relative_to='r_shoulder'>0 0 0 0 -0 0</pose>
        <parent>r_shoulder</parent>
        <child>r_shoulder_x</child>
        <axis>
          <xyz>1 0 0</xyz>
          <limit>
            <lower>-3.14</lower>
            <upper>0.174</upper>
            <effort>10</effort>
            <velocity>0</velocity>
          </limit>
          <dynamics>
            <damping>0.1</damping>
            <friction>0.1</friction>
            <spring_reference>0</spring_reference>
            <spring_stiffness>0</spring_stiffness>
          </dynamics>
        </axis>
      </joint>
      <link name='r_shoulder_x'>
        <pose relative_to='r_shoulder_roll'>0 0 0 0 -0 0</pose>
        <inertial>
          <pose>0 0 -0.019 0 -0 0</pose>
          <mass>0.158</mass>
          <inertia>
            <ixx>68870</ixx>
            <ixy>5.393</ixy>
            <ixz>-915.5</ixz>
            <iyy>78950</iyy>
            <iyz>0.4512</iyz>
            <izz>42350</izz>
          </inertia>
        </inertial>
        <collision name='r_shoulder_x_collision'>
          <pose>0 0 -0.02 0 -0 0</pose>
          <geometry>
            <cylinder>
              <length>0.04</length>
              <radius>0.035</radius>
            </cylinder>
          </geometry>
          <max_contacts>10</max_contacts>
          <surface>
            <contact>
              <ode/>
            </contact>
            <bounce/>
            <friction>
              <torsional>
                <ode/>
              </torsional>
              <ode/>
            </friction>
          </surface>
        </collision>
        <visual name='r_shoulder_x_visual'>
          <pose>0 0 0 0 -0 0</pose>
          <geometry>
            <mesh>
              <scale>1 1 1</scale>
              <uri>file:///home/reachy/reachy_ws/install/reachy_description/share/reachy_description/meshes/shoulder_x.dae</uri>
            </mesh>
          </geometry>
        </visual>
        <self_collide>0</self_collide>
        <enable_wind>0</enable_wind>
        <kinematic>0</kinematic>
      </link>
      <joint name='r_arm_yaw' type='revolute'>
        <pose relative_to='r_shoulder_x'>0 0 0 0 -0 0</pose>
        <parent>r_shoulder_x</parent>
        <child>r_upper_arm</child>
        <axis>
          <xyz>0 0 1</xyz>
          <limit>
            <lower>-1.57</lower>
            <upper>1.57</upper>
            <effort>10</effort>
            <velocity>0</velocity>
          </limit>
          <dynamics>
            <damping>0.1</damping>
            <friction>0.1</friction>
            <spring_reference>0</spring_reference>
            <spring_stiffness>0</spring_stiffness>
          </dynamics>
        </axis>
      </joint>
      <link name='r_upper_arm'>
        <pose relative_to='r_arm_yaw'>0 0 0 0 -0 0</pose>
        <inertial>
          <pose>-0.004 0 -0.1426 0 -0 0</pose>
          <mass>0.43</mass>
          <inertia>
            <ixx>0.003264</ixx>
            <ixy>-4.027e-08</ixy>
            <ixz>0.0001395</ixz>
            <iyy>0.003345</iyy>
            <iyz>1.885e-06</iyz>
            <izz>0.0002616</izz>
          </inertia>
        </inertial>
        <collision name='r_upper_arm_collision'>
          <pose>0 0 -0.16 0 -0 0</pose>
          <geometry>
            <cylinder>
              <length>0.25</length>
              <radius>0.04</radius>
            </cylinder>
          </geometry>
          <max_contacts>10</max_contacts>
          <surface>
            <contact>
              <ode/>
            </contact>
            <bounce/>
            <friction>
              <torsional>
                <ode/>
              </torsional>
              <ode/>
            </friction>
          </surface>
        </collision>
        <visual name='r_upper_arm_visual'>
          <pose>0 0 -0.0526 0 -0 0</pose>
          <geometry>
            <mesh>
              <scale>1 1 1</scale>
              <uri>file:///home/reachy/reachy_ws/install/reachy_description/share/reachy_description/meshes/upper_arm.dae</uri>
            </mesh>
          </geometry>
        </visual>
        <self_collide>0</self_collide>
        <enable_wind>0</enable_wind>
        <kinematic>0</kinematic>
      </link>
      <joint name='r_elbow_pitch' type='revolute'>
        <pose relative_to='r_upper_arm'>0 0 -0.28 0 -0 0</pose>
        <parent>r_upper_arm</parent>
        <child>r_forearm</child>
        <axis>
          <xyz>0 1 0</xyz>
          <limit>
            <lower>-2.182</lower>
            <upper>0</upper>
            <effort>10</effort>
            <velocity>0</velocity>
          </limit>
          <dynamics>
            <damping>0.1</damping>
            <friction>0.1</friction>
            <spring_reference>0</spring_reference>
            <spring_stiffness>0</spring_stiffness>
          </dynamics>
        </axis>
      </joint>
      <link name='r_forearm'>
        <pose relative_to='r_elbow_pitch'>0 0 0 0 -0 0</pose>
        <inertial>
          <pose>-0.008 0 -0.058 0 -0 0</pose>
          <mass>0.162</mass>
          <inertia>
            <ixx>0.0002532</ixx>
            <ixy>-2.999e-08</ixy>
            <ixz>1.448e-05</ixz>
            <iyy>0.0002538</iyy>
            <iyz>-4.323e-08</iyz>
            <izz>0.0001234</izz>
          </inertia>
        </inertial>
        <collision name='r_forearm_collision'>
          <pose>0 0 -0.058 0 -0 0</pose>
          <geometry>
            <cylinder>
              <length>0.09</length>
              <radius>0.04</radius>
            </cylinder>
          </geometry>
          <max_contacts>10</max_contacts>
          <surface>
            <contact>
              <ode/>
            </contact>
            <bounce/>
            <friction>
              <torsional>
                <ode/>
              </torsional>
              <ode/>
            </friction>
          </surface>
        </collision>
        <visual name='r_forearm_visual'>
          <pose>0 0 0 0 -0 0</pose>
          <geometry>
            <mesh>
              <scale>1 1 1</scale>
              <uri>file:///home/reachy/reachy_ws/install/reachy_description/share/reachy_description/meshes/forearm.dae</uri>
            </mesh>
          </geometry>
        </visual>
        <self_collide>0</self_collide>
        <enable_wind>0</enable_wind>
        <kinematic>0</kinematic>
      </link>
      <joint name='r_forearm_yaw' type='revolute'>
        <pose relative_to='r_forearm'>0 0 0 0 -0 0</pose>
        <parent>r_forearm</parent>
        <child>r_wrist</child>
        <axis>
          <xyz>0 0 1</xyz>
          <limit>
            <lower>-1.745</lower>
            <upper>1.745</upper>
            <effort>10</effort>
            <velocity>0</velocity>
          </limit>
          <dynamics>
            <damping>0.1</damping>
            <friction>0.1</friction>
            <spring_reference>0</spring_reference>
            <spring_stiffness>0</spring_stiffness>
          </dynamics>
        </axis>
      </joint>
      <link name='r_wrist'>
        <pose relative_to='r_forearm_yaw'>0 0 0 0 -0 0</pose>
        <inertial>
          <pose>0 0 -0.193 0 -0 0</pose>
          <mass>0.197</mass>
          <inertia>
            <ixx>0.0006157</ixx>
            <ixy>5.706e-08</ixy>
            <ixz>-1.045e-05</ixz>
            <iyy>0.000628</iyy>
            <iyz>4.862e-07</iyz>
            <izz>0.000105</izz>
          </inertia>
        </inertial>
        <collision name='r_wrist_collision'>
          <pose>0 0 -0.18 0 -0 0</pose>
          <geometry>
            <cylinder>
              <length>0.14</length>
              <radius>0.035</radius>
            </cylinder>
          </geometry>
          <max_contacts>10</max_contacts>
          <surface>
            <contact>
              <ode/>
            </contact>
            <bounce/>
            <friction>
              <torsional>
                <ode/>
              </torsional>
              <ode/>
            </friction>
          </surface>
        </collision>
        <visual name='r_wrist_visual'>
          <pose>0 0 -0.1 0 -0 0</pose>
          <geometry>
            <mesh>
              <scale>1 1 1</scale>
              <uri>file:///home/reachy/reachy_ws/install/reachy_description/share/reachy_description/meshes/wrist.dae</uri>
            </mesh>
          </geometry>
        </visual>
        <self_collide>0</self_collide>
        <enable_wind>0</enable_wind>
        <kinematic>0</kinematic>
      </link>
      <joint name='r_wrist_pitch' type='revolute'>
        <pose relative_to='r_wrist'>0 0 -0.25 0 -0 0</pose>
        <parent>r_wrist</parent>
        <child>r_wrist2hand</child>
        <axis>
          <xyz>0 1 0</xyz>
          <limit>
            <lower>-0.785</lower>
            <upper>0.785</upper>
            <effort>10</effort>
            <velocity>0</velocity>
          </limit>
          <dynamics>
            <damping>0.1</damping>
            <friction>0.1</friction>
            <spring_reference>0</spring_reference>
            <spring_stiffness>0</spring_stiffness>
          </dynamics>
        </axis>
      </joint>
      <link name='r_wrist2hand'>
        <pose relative_to='r_wrist_pitch'>0 0 0 0 -0 0</pose>
        <inertial>
          <pose>0 0 0.014 0 -0 0</pose>
          <mass>0.01</mass>
          <inertia>
            <ixx>6.75e-06</ixx>
            <ixy>3.732e-11</ixy>
            <ixz>-1.581e-11</ixz>
            <iyy>6.06e-06</iyy>
            <iyz>-1.746e-12</iyz>
            <izz>5.774e-06</izz>
          </inertia>
        </inertial>
        <collision name='r_wrist2hand_collision'>
          <pose>0 0 -0.03 0 -0 0</pose>
          <geometry>
            <cylinder>
              <length>0.06</length>
              <radius>0.03</radius>
            </cylinder>
          </geometry>
          <max_contacts>10</max_contacts>
          <surface>
            <contact>
              <ode/>
            </contact>
            <bounce/>
            <friction>
              <torsional>
                <ode/>
              </torsional>
              <ode/>
            </friction>
          </surface>
        </collision>
        <visual name='r_wrist2hand_visual'>
          <pose>0 0 0 0 -0 0</pose>
          <geometry>
            <mesh>
              <scale>1 1 1</scale>
              <uri>file:///home/reachy/reachy_ws/install/reachy_description/share/reachy_description/meshes/wrist2hand.dae</uri>
            </mesh>
          </geometry>
        </visual>
        <self_collide>0</self_collide>
        <enable_wind>0</enable_wind>
        <kinematic>0</kinematic>
      </link>
      <joint name='r_wrist_roll' type='revolute'>
        <pose relative_to='r_wrist2hand'>0 0 -0.0325 0 -0 0</pose>
        <parent>r_wrist2hand</parent>
        <child>r_gripper_thumb</child>
        <axis>
          <xyz>1 0 0</xyz>
          <limit>
            <lower>-0.785</lower>
            <upper>0.785</upper>
            <effort>10</effort>
            <velocity>0</velocity>
          </limit>
          <dynamics>
            <damping>0.1</damping>
            <friction>0.1</friction>
            <spring_reference>0</spring_reference>
            <spring_stiffness>0</spring_stiffness>
          </dynamics>
        </axis>
      </joint>
      <link name='r_gripper_thumb'>
        <pose relative_to='r_wrist_roll'>0 0 0 0 -0 0</pose>
        <inertial>
          <pose>0.031816 -0.008023 -0.000489 0 1.57 0</pose>
          <mass>0.174</mass>
          <inertia>
            <ixx>0.000110334</ixx>
            <ixy>-3.4432e-05</ixy>
            <ixz>4.02537e-06</ixz>
            <iyy>0.000151302</iyy>
            <iyz>5.55736e-07</iyz>
            <izz>0.000219399</izz>
          </inertia>
        </inertial>
        <collision name='r_gripper_thumb_collision'>
          <pose>0 0 0 3.14159 1.57079 3.14159</pose>
          <geometry>
            <mesh>
              <scale>1 1 1</scale>
              <uri>file:///home/reachy/reachy_ws/install/reachy_description/share/reachy_description/meshes/r_gripper_thumb.dae</uri>
            </mesh>
          </geometry>
          <surface>
            <contact>
              <ode/>
            </contact>
            <friction>
              <ode/>
              <torsional>
                <ode/>
              </torsional>
            </friction>
            <bounce/>
          </surface>
          <max_contacts>10</max_contacts>
        </collision>
        <visual name='r_gripper_thumb_visual'>
          <pose>0 0 0 3.14159 1.57079 3.14159</pose>
          <geometry>
            <mesh>
              <scale>1 1 1</scale>
              <uri>file:///home/reachy/reachy_ws/install/reachy_description/share/reachy_description/meshes/r_gripper_thumb.dae</uri>
            </mesh>
          </geometry>
        </visual>
        <self_collide>1</self_collide>
        <enable_wind>0</enable_wind>
        <kinematic>0</kinematic>
      </link>
      <joint name='r_gripper' type='revolute'>
        <pose relative_to='r_gripper_thumb'>0 -0.037 -0.03998 0 -0 0</pose>
        <parent>r_gripper_thumb</parent>
        <child>r_gripper_finger</child>
        <axis>
          <xyz>1 0 0</xyz>
          <limit>
            <lower>-1.2</lower>
            <upper>0.35</upper>
            <effort>10</effort>
            <velocity>0</velocity>
          </limit>
          <dynamics>
            <damping>0.1</damping>
            <friction>0.1</friction>
            <spring_reference>0</spring_reference>
            <spring_stiffness>0</spring_stiffness>
          </dynamics>
        </axis>
        <physics>
          <provide_feedback>1</provide_feedback>
          <ode>
            <limit>
              <cfm>0</cfm>
              <erp>0.2</erp>
            </limit>
            <provide_feedback>1</provide_feedback>
          </ode>
        </physics>
      </joint>
      <link name='r_gripper_finger'>
        <pose relative_to='r_gripper'>0 0 0 0 -0 0</pose>
        <inertial>
          <pose>-0.005 -0.043 0 0 1.57 0</pose>
          <mass>0.035</mass>
          <inertia>
            <ixx>9.166e-05</ixx>
            <ixy>-6.559e-06</ixy>
            <ixz>-3.952e-08</ixz>
            <iyy>1.062e-05</iyy>
            <iyz>5.276e-09</iyz>
            <izz>8.704e-05</izz>
          </inertia>
        </inertial>
        <collision name='r_gripper_finger_collision'>
          <pose>0 0 0 3.14159 1.57079 3.14159</pose>
          <geometry>
            <mesh>
              <scale>1 1 1</scale>
              <uri>file:///home/reachy/reachy_ws/install/reachy_description/share/reachy_description/meshes/r_gripper_finger.dae</uri>
            </mesh>
          </geometry>
          <surface>
            <contact>
              <ode/>
            </contact>
            <friction>
              <ode/>
              <torsional>
                <ode/>
              </torsional>
            </friction>
            <bounce/>
          </surface>
          <max_contacts>10</max_contacts>
        </collision>
        <visual name='r_gripper_finger_visual'>
          <pose>0 0 0 3.14159 1.57079 3.14159</pose>
          <geometry>
            <mesh>
              <scale>1 1 1</scale>
              <uri>file:///home/reachy/reachy_ws/install/reachy_description/share/reachy_description/meshes/r_gripper_finger.dae</uri>
            </mesh>
          </geometry>
        </visual>
        <self_collide>1</self_collide>
        <enable_wind>0</enable_wind>
        <kinematic>0</kinematic>
      </link>
      <plugin name='gazebo_ros_ft' filename='libgazebo_ros_ft_sensor.so'>
        <ros>
          <namespace>/r_force_sensor</namespace>
          <argument>wrench:=r_gripper_ft_sensor</argument>
        </ros>
        <joint_name>r_gripper</joint_name>
        <update_rate>200</update_rate>
        <update_rate>1</update_rate>
        <gaussian_noise>0.01</gaussian_noise>
      </plugin>
      <plugin name='gazebo_ros_ft' filename='libgazebo_ros_ft_sensor.so'>
        <ros>
          <namespace>/l_force_sensor</namespace>
          <argument>wrench:=l_gripper_ft_sensor</argument>
        </ros>
        <joint_name>l_gripper</joint_name>
        <update_rate>200</update_rate>
        <update_rate>1</update_rate>
        <gaussian_noise>0.01</gaussian_noise>
      </plugin>
      <static>0</static>
      <plugin name='gazebo_ros2_control' filename='libgazebo_ros2_control.so'>
        <parameters>/home/reachy/reachy_ws/install/reachy_moveit_config/share/reachy_moveit_config/config/ros2_controllers.yaml</parameters>
        <robotNamespace>/reachy</robotNamespace>
      </plugin>
      <pose>0 0 0 0 -0 0</pose>
    </model>
    <model name='table'>
      <static>1</static>
      <link name='link'>
        <collision name='surface'>
          <pose>0 0 1 0 -0 0</pose>
          <geometry>
            <box>
              <size>1.5 0.8 0.03</size>
            </box>
          </geometry>
          <surface>
            <friction>
              <ode>
                <mu>0.6</mu>
                <mu2>0.6</mu2>
              </ode>
              <torsional>
                <ode/>
              </torsional>
            </friction>
            <contact>
              <ode/>
            </contact>
            <bounce/>
          </surface>
          <max_contacts>10</max_contacts>
        </collision>
        <visual name='visual1'>
          <pose>0 0 1 0 -0 0</pose>
          <geometry>
            <box>
              <size>1.5 0.8 0.03</size>
            </box>
          </geometry>
          <material>
            <script>
              <uri>file://media/materials/scripts/gazebo.material</uri>
              <name>Gazebo/Wood</name>
            </script>
          </material>
        </visual>
        <collision name='front_left_leg'>
          <pose>0.68 0.38 0.5 0 -0 0</pose>
          <geometry>
            <cylinder>
              <radius>0.02</radius>
              <length>1</length>
            </cylinder>
          </geometry>
          <max_contacts>10</max_contacts>
          <surface>
            <contact>
              <ode/>
            </contact>
            <bounce/>
            <friction>
              <torsional>
                <ode/>
              </torsional>
              <ode/>
            </friction>
          </surface>
        </collision>
        <visual name='front_left_leg'>
          <pose>0.68 0.38 0.5 0 -0 0</pose>
          <geometry>
            <cylinder>
              <radius>0.02</radius>
              <length>1</length>
            </cylinder>
          </geometry>
          <material>
            <script>
              <uri>file://media/materials/scripts/gazebo.material</uri>
              <name>Gazebo/Grey</name>
            </script>
          </material>
        </visual>
        <collision name='front_right_leg'>
          <pose>0.68 -0.38 0.5 0 -0 0</pose>
          <geometry>
            <cylinder>
              <radius>0.02</radius>
              <length>1</length>
            </cylinder>
          </geometry>
          <max_contacts>10</max_contacts>
          <surface>
            <contact>
              <ode/>
            </contact>
            <bounce/>
            <friction>
              <torsional>
                <ode/>
              </torsional>
              <ode/>
            </friction>
          </surface>
        </collision>
        <visual name='front_right_leg'>
          <pose>0.68 -0.38 0.5 0 -0 0</pose>
          <geometry>
            <cylinder>
              <radius>0.02</radius>
              <length>1</length>
            </cylinder>
          </geometry>
          <material>
            <script>
              <uri>file://media/materials/scripts/gazebo.material</uri>
              <name>Gazebo/Grey</name>
            </script>
          </material>
        </visual>
        <collision name='back_right_leg'>
          <pose>-0.68 -0.38 0.5 0 -0 0</pose>
          <geometry>
            <cylinder>
              <radius>0.02</radius>
              <length>1</length>
            </cylinder>
          </geometry>
          <max_contacts>10</max_contacts>
          <surface>
            <contact>
              <ode/>
            </contact>
            <bounce/>
            <friction>
              <torsional>
                <ode/>
              </torsional>
              <ode/>
            </friction>
          </surface>
        </collision>
        <visual name='back_right_leg'>
          <pose>-0.68 -0.38 0.5 0 -0 0</pose>
          <geometry>
            <cylinder>
              <radius>0.02</radius>
              <length>1</length>
            </cylinder>
          </geometry>
          <material>
            <script>
              <uri>file://media/materials/scripts/gazebo.material</uri>
              <name>Gazebo/Grey</name>
            </script>
          </material>
        </visual>
        <collision name='back_left_leg'>
          <pose>-0.68 0.38 0.5 0 -0 0</pose>
          <geometry>
            <cylinder>
              <radius>0.02</radius>
              <length>1</length>
            </cylinder>
          </geometry>
          <max_contacts>10</max_contacts>
          <surface>
            <contact>
              <ode/>
            </contact>
            <bounce/>
            <friction>
              <torsional>
                <ode/>
              </torsional>
              <ode/>
            </friction>
          </surface>
        </collision>
        <visual name='back_left_leg'>
          <pose>-0.68 0.38 0.5 0 -0 0</pose>
          <geometry>
            <cylinder>
              <radius>0.02</radius>
              <length>1</length>
            </cylinder>
          </geometry>
          <material>
            <script>
              <uri>file://media/materials/scripts/gazebo.material</uri>
              <name>Gazebo/Grey</name>
            </script>
          </material>
        </visual>
        <self_collide>0</self_collide>
        <enable_wind>0</enable_wind>
        <kinematic>0</kinematic>
      </link>
      <pose>1.12176 -0.154403 0 0 -0 0</pose>
    </model>
    <model name='beer'>
      <link name='link'>
        <pose>0 0 0.115 0 -0 0</pose>
        <inertial>
          <mass>0.39</mass>
          <inertia>
            <ixx>0.00058</ixx>
            <ixy>0</ixy>
            <ixz>0</ixz>
            <iyy>0.00058</iyy>
            <iyz>0</iyz>
            <izz>0.00019</izz>
          </inertia>
          <pose>0 0 0 0 -0 0</pose>
        </inertial>
        <collision name='collision'>
          <geometry>
            <cylinder>
              <radius>0.055</radius>
              <length>0.23</length>
            </cylinder>
          </geometry>
          <max_contacts>10</max_contacts>
          <surface>
            <contact>
              <ode/>
            </contact>
            <bounce/>
            <friction>
              <torsional>
                <ode/>
              </torsional>
              <ode/>
            </friction>
          </surface>
        </collision>
        <visual name='visual'>
          <geometry>
            <cylinder>
              <radius>0.055</radius>
              <length>0.23</length>
            </cylinder>
          </geometry>
          <material>
            <script>
              <uri>model://beer/materials/scripts</uri>
              <uri>model://beer/materials/textures</uri>
              <name>Beer/Diffuse</name>
            </script>
          </material>
        </visual>
        <self_collide>0</self_collide>
        <enable_wind>0</enable_wind>
        <kinematic>0</kinematic>
      </link>
      <pose>0.313988 0.095818 0 0 -0 0</pose>
    </model>
    <state world_name='default'>
      <sim_time>1367 764000000</sim_time>
      <real_time>4495 362019105</real_time>
      <wall_time>1677070121 426028063</wall_time>
      <iterations>1367764</iterations>
      <model name='beer'>
        <pose>0.355506 -0.142289 0.740232 4e-06 3e-06 0.000137</pose>
        <scale>1 1 1</scale>
        <link name='link'>
          <pose>0.355507 -0.14229 0.855232 4e-06 3e-06 0.000137</pose>
          <velocity>0 0 0 0 -0 0</velocity>
          <acceleration>1.74566 -2.18179 -3.2028 1.19875 1.29526 -2.67273</acceleration>
          <wrench>0.680808 -0.850897 -1.24909 0 -0 0</wrench>
        </link>
      </model>
      <model name='ground_plane'>
        <pose>0 0 0 0 -0 0</pose>
        <scale>1 1 1</scale>
        <link name='link'>
          <pose>0 0 0 0 -0 0</pose>
          <velocity>0 0 0 0 -0 0</velocity>
          <acceleration>0 0 0 0 -0 0</acceleration>
          <wrench>0 0 0 0 -0 0</wrench>
        </link>
      </model>
      <model name='reachy'>
        <pose>-2.4e-05 5.5e-05 -1e-06 5.6e-05 2.3e-05 -0.000105</pose>
        <scale>1 1 1</scale>
        <link name='head_x'>
          <pose>0.015 -1.2e-05 1.09491 0.00277 0.176231 -0.003292</pose>
          <velocity>8e-06 -2e-06 2.2e-05 0.599209 -0.003382 0.406439</velocity>
          <acceleration>0.006694 0.0045 0.049906 2.77364 0.629647 -0.839056</acceleration>
          <wrench>7e-06 5e-06 5e-05 0 -0 0</wrench>
        </link>
        <link name='head_y'>
          <pose>0.015 -1.2e-05 1.09485 0.004285 0.61676 -0.003555</pose>
          <velocity>6e-06 -1e-05 4.1e-05 0.79552 0.295356 0.67463</velocity>
          <acceleration>0.012484 -0.052929 0.087569 1.1649 -0.979481 0.66173</acceleration>
          <wrench>1.2e-05 -5.3e-05 8.8e-05 0 -0 0</wrench>
        </link>
        <link name='head_z'>
          <pose>0.015 -1.2e-05 1.09488 0.405901 0.47715 0.742758</pose>
          <velocity>1.7e-05 -6e-06 3.6e-05 0.16595 0.308244 -0.224544</velocity>
          <acceleration>0.000157 0.005518 -0.002941 -1.87623 -1.23821 -0.421589</acceleration>
          <wrench>3.7e-05 0.001313 -0.0007 0 -0 0</wrench>
        </link>
        <link name='l_antenna_link'>
          <pose>0.002865 0.013841 1.20894 -0.35123 0.342592 1.78628</pose>
          <velocity>0.038301 -0.016238 0.006102 0.048657 0.376466 0.032702</velocity>
          <acceleration>0.075613 -0.047094 0.021305 0.9475 1.02067 0.376965</acceleration>
          <wrench>0.000302 -0.000188 8.5e-05 0 -0 0</wrench>
        </link>
        <link name='l_forearm'>
          <pose>0.096933 0.285663 0.755387 2.64655 -0.641406 -2.88094</pose>
          <velocity>0.00242 -0.0048 -0.000467 1.1212 -0.14271 -0.01939</velocity>
          <acceleration>0.001676 -0.000343 0.007232 -1.96775 1.48202 -2.25777</acceleration>
          <wrench>0.000271 -5.6e-05 0.001172 0 -0 0</wrench>
        </link>
        <link name='l_gripper_finger'>
          <pose>0.32337 0.226766 0.930952 -0.873936 -1.55896 0.876323</pose>
          <velocity>1.08324 -0.206918 -1.45779 1.15513 -0.078329 -0.02418</velocity>
          <acceleration>-0.006407 0.013633 -0.021595 2.78416 -1.52704 0.817892</acceleration>
          <wrench>-0.000224 0.000477 -0.000756 0 -0 0</wrench>
        </link>
        <link name='l_gripper_thumb'>
          <pose>0.283476 0.189675 0.931594 -0.873116 -1.55896 0.875497</pose>
          <velocity>1.08551 -0.206529 -1.25257 1.15512 -0.078341 -0.024542</velocity>
          <acceleration>-0.004465 0.00895 -0.012813 0.063869 1.37134 -2.91727</acceleration>
          <wrench>-0.000777 0.001557 -0.00223 0 -0 0</wrench>
        </link>
        <link name='l_shoulder'>
          <pose>1.7e-05 0.19 0.999992 -0.011567 -0.380818 0.007888</pose>
          <velocity>4e-06 -1e-06 1.1e-05 -0.003851 -0.005278 0.001642</velocity>
          <acceleration>-0.011596 -0.001198 0.03861 2.07931 0.92064 -0.945068</acceleration>
          <wrench>-0.000615 -6.4e-05 0.002046 0 -0 0</wrench>
        </link>
        <link name='l_shoulder_x'>
          <pose>-0.000239 0.189901 0.9999 0.346689 -0.380407 0.006372</pose>
          <velocity>-9.6e-05 -4.1e-05 -2.6e-05 -0.017094 -0.005076 -0.00425</velocity>
          <acceleration>0.00094 -0.000539 0.005978 0.000446 0.000368 -0.000893</acceleration>
          <wrench>0.000149 -8.5e-05 0.000945 0 -0 0</wrench>
        </link>
        <link name='l_upper_arm'>
          <pose>-0.000239 0.189901 0.999899 0.411092 -0.308995 -0.183584</pose>
          <velocity>-0.000104 -3.8e-05 -2.8e-05 0.853912 0.853343 -2.19607</velocity>
          <acceleration>0.002256 -0.001266 0.006751 -2.1516 -0.623088 1.37148</acceleration>
          <wrench>0.00097 -0.000544 0.002903 0 -0 0</wrench>
        </link>
        <link name='l_wrist'>
          <pose>0.096937 0.285662 0.755399 -3.12526 -0.788157 2.64512</pose>
          <velocity>0.004132 -0.005107 0.001458 1.12121 -0.142715 -0.019384</velocity>
          <acceleration>-0.00011 0.002364 0.010262 -0.069469 -0.131958 1.6975</acceleration>
          <wrench>-2.2e-05 0.000466 0.002022 0 -0 0</wrench>
        </link>
        <link name='l_wrist2hand'>
          <pose>0.254722 0.204828 0.931663 -1.36031 -1.55892 0.875495</pose>
          <velocity>1.08539 -0.205876 -1.05726 1.15509 -0.078388 -0.020172</velocity>
          <acceleration>-0.0059 0.005878 0.003104 3.10305 -1.27942 -1.97297</acceleration>
          <wrench>-5.9e-05 5.9e-05 3.1e-05 0 -0 0</wrench>
        </link>
        <link name='r_antenna_link'>
          <pose>0.058474 -0.07729 1.16895 0.828271 -0.942965 0.942077</pose>
          <velocity>0.005457 -0.022063 -0.02616 0.212979 0.158571 -0.156492</velocity>
          <acceleration>-0.166958 0.100612 0.059457 -1.1798 0.377692 2.0544</acceleration>
          <wrench>-0.000668 0.000402 0.000238 0 -0 0</wrench>
        </link>
        <link name='r_forearm'>
          <pose>-0.00013 -0.190038 0.719971 -0.000151 0.00041 -0.000237</pose>
          <velocity>-5.7e-05 0.000794 -4.6e-05 0.002814 -0.000672 -9.7e-05</velocity>
          <acceleration>-0.026569 0.009483 -0.06679 0.016775 -0.470152 -0.069014</acceleration>
          <wrench>-0.004304 0.001536 -0.01082 0 -0 0</wrench>
        </link>
        <link name='r_gripper_finger'>
          <pose>-0.000288 -0.227097 0.397494 -0.000333 0.000798 -0.000243</pose>
          <velocity>0.00171 0.003707 -0.002032 0.054387 -0.024478 0.000399</velocity>
          <acceleration>0.122048 -0.063015 -0.102261 0.348862 -0.026483 2.36195</acceleration>
          <wrench>0.004272 -0.002206 -0.003579 0 -0 0</wrench>
        </link>
        <link name='r_gripper_thumb'>
          <pose>-0.000247 -0.190084 0.437463 -0.000335 0.0008 -0.000244</pose>
          <velocity>0.000716 0.00156 -3.6e-05 0.053746 -0.024402 0.000313</velocity>
          <acceleration>-0.298716 0.012995 0.164359 0.308403 0.200307 2.08902</acceleration>
          <wrench>-0.051977 0.002261 0.028598 0 -0 0</wrench>
        </link>
        <link name='r_shoulder'>
          <pose>-1.4e-05 -0.189997 0.999992 8.3e-05 3.8e-05 -6.8e-05</pose>
          <velocity>-9e-06 2e-06 0.000176 -0.000294 -0.010045 -3.3e-05</velocity>
          <acceleration>-0.005944 -0.000599 0.002546 0.125865 -0.344576 -0.025336</acceleration>
          <wrench>-0.000315 -3.2e-05 0.000135 0 -0 0</wrench>
        </link>
        <link name='r_shoulder_x'>
          <pose>-1.4e-05 -0.189997 0.999973 -0.000149 0.000411 -0.000236</pose>
          <velocity>-3e-06 5e-06 -3.4e-05 0.002812 0.000148 -9.3e-05</velocity>
          <acceleration>-0.003469 0.005831 -0.05559 3e-06 -1e-06 3.5e-05</acceleration>
          <wrench>-0.000548 0.000921 -0.008783 0 -0 0</wrench>
        </link>
        <link name='r_upper_arm'>
          <pose>-1.4e-05 -0.189997 0.999971 -0.000149 0.00041 -0.000236</pose>
          <velocity>-8e-06 8e-06 -4.4e-05 0.00281 0.000141 -0.000103</velocity>
          <acceleration>-0.016931 0.010452 -0.065209 -0.005977 -0.028147 0.045259</acceleration>
          <wrench>-0.00728 0.004494 -0.02804 0 -0 0</wrench>
        </link>
        <link name='r_wrist'>
          <pose>-0.000132 -0.190037 0.71997 -0.000144 0.000426 -0.000247</pose>
          <velocity>-7.2e-05 0.000794 -4.8e-05 0.002809 -0.000642 -0.000265</velocity>
          <acceleration>-0.055611 0.006801 -0.063881 -0.001419 -0.274625 0.080142</acceleration>
          <wrench>-0.010955 0.00134 -0.012584 0 -0 0</wrench>
        </link>
        <link name='r_wrist2hand'>
          <pose>-0.000232 -0.190078 0.469971 -0.000215 0.000432 -0.000248</pose>
          <velocity>1.6e-05 0.00149 -5.4e-05 0.002681 -0.020336 -0.000464</velocity>
          <acceleration>-0.173569 -0.006852 -0.074832 2.78431 1.1417 2.51086</acceleration>
          <wrench>-0.001736 -6.9e-05 -0.000748 0 -0 0</wrench>
        </link>
        <link name='torso'>
          <pose>-2e-06 -1e-06 0.999999 5.6e-05 2.3e-05 -0.000105</pose>
          <velocity>-2e-06 0 2e-06 -4.3e-05 -6e-06 -7.4e-05</velocity>
          <acceleration>-0.000547 -0.000201 0.001169 -0.077644 0.009742 -0.037235</acceleration>
          <wrench>-0.00029 -0.000106 0.00062 0 -0 0</wrench>
        </link>
      </model>
      <model name='table'>
        <pose>0.618528 -0.015107 -0.274767 0 -0 1.56835</pose>
        <scale>1 1 1</scale>
        <link name='link'>
          <pose>0.618528 -0.015107 -0.274767 0 -0 1.56835</pose>
          <velocity>0 0 0 0 -0 0</velocity>
          <acceleration>0 0 0 0 -0 0</acceleration>
          <wrench>0 0 0 0 -0 0</wrench>
        </link>
      </model>
      <light name='sun'>
        <pose>0 0 10 0 -0 0</pose>
      </light>
    </state>
    <gui fullscreen='0'>
      <camera name='user_camera'>
        <pose>0.592079 -1.25558 3.17374 0 0.977796 1.4042</pose>
        <view_controller>orbit</view_controller>
        <projection_type>perspective</projection_type>
      </camera>
    </gui>
  </world>
</sdf>
